 <robot name="test_robot">
   <link name="base_link" />


   <link name="link1" />
   <link name="link2" />
   <link name="link3" />
   <link name="link4" />
 
   <!-- New joint to connect base_link and link1 -->
   <joint name="base_joint" type="fixed">
     <parent link="base_link"/>
     <child link="link1"/>
     <origin xyz="0 0 0" rpy="0 0 0" />
   </joint>



   <joint name="joint1" type="continuous">
     <parent link="link1"/>
     <child link="link2"/>
     <origin xyz="0.5 0.3 0" rpy="0 0 0" />
     <axis xyz="-0.9 0.15 0" />
   </joint>
 
   <joint name="joint2" type="continuous">
     <parent link="link1"/>
     <child link="link3"/>
     <origin xyz="-0.2 0.5 0" rpy="0 0 1.57" />
     <axis xyz="-1 0 0" />
   </joint>
 
   <joint name="joint3" type="continuous">
     <parent link="link3"/>
     <child link="link4"/>
     <origin xyz="0.5 0 0" rpy="0 0 -1.57" />
     <axis xyz="0.707 -0.707 0" />
   </joint>
</robot>